2020-08-25 16:18:37,389 : INFO :: XBeeSerialPort '/dev/ttyUSB1' port opened
2020-08-25 16:18:37,547 : INFO :: {'context': 'UDP_CONN', 'msg': 'Initialized UDP port at 127.0.0.1:14555 for drone ID:0013A200419B5AD8'}
2020-08-25 16:18:43,708 : ERROR :: read failed: device reports readiness to read but returned no data (device disconnected or multiple access on port?)
Traceback (most recent call last):
  File "/home/abhish/anaconda3/envs/xbee/lib/python3.6/site-packages/serial/serialposix.py", line 501, in read
    'device reports readiness to read but returned no data '
serial.serialutil.SerialException: device reports readiness to read but returned no data (device disconnected or multiple access on port?)

During handling of the above exception, another exception occurred:

Traceback (most recent call last):
  File "/home/abhish/anaconda3/envs/xbee/lib/python3.6/site-packages/digi/xbee/reader.py", line 572, in run
    self.__xbee.operating_mode)
  File "/home/abhish/anaconda3/envs/xbee/lib/python3.6/site-packages/digi/xbee/serial.py", line 221, in wait_for_frame
    xbee_packet[0] = self.read_byte()
  File "/home/abhish/anaconda3/envs/xbee/lib/python3.6/site-packages/digi/xbee/serial.py", line 133, in read_byte
    byte = bytearray(self.read(1))
  File "/home/abhish/anaconda3/envs/xbee/lib/python3.6/site-packages/serial/serialposix.py", line 509, in read
    raise SerialException('read failed: {}'.format(e))
serial.serialutil.SerialException: read failed: device reports readiness to read but returned no data (device disconnected or multiple access on port?)
